<mujoco model="robotiq_arg2f_140_model">
    <compiler angle="radian"/>
    <size njmax="500" nconmax="100" />
    <asset>
        <mesh name="robotiq_arg2f_base_link_collision" file="meshes/robotiq_140_gripper/robotiq_arg2f_base_link_collision.stl" />
        <mesh name="robotiq_arg2f_140_outer_knuckle_collision" file="meshes/robotiq_140_gripper/robotiq_arg2f_140_outer_knuckle_collision.stl" />
        <mesh name="robotiq_arg2f_140_outer_finger_collision" file="meshes/robotiq_140_gripper/robotiq_arg2f_140_outer_finger_collision.stl" />
        <mesh name="robotiq_arg2f_140_inner_finger_collision" file="meshes/robotiq_140_gripper/robotiq_arg2f_140_inner_finger_collision.stl" />
        <mesh name="robotiq_arg2f_140_inner_knuckle_collision" file="meshes/robotiq_140_gripper/robotiq_arg2f_140_inner_knuckle_collision.stl" />
    </asset>

    <actuator>
        <position ctrllimited="true" ctrlrange="-0.7 0.0" joint="left_outer_knuckle_joint" kp="1" name="gripper_left_outer_knuckle_joint" forcelimited="true" forcerange="-20 20"/>
        <position ctrllimited="true" ctrlrange="0 0.7" joint="left_inner_finger_joint" kp="1" name="gripper_left_inner_finger_joint" forcelimited="true" forcerange="-20 20"/>
        <position ctrllimited="true" ctrlrange="-0.7 0.0" joint="left_inner_knuckle_joint" kp="1" name="gripper_left_inner_knuckle_joint" forcelimited="true" forcerange="-20 20"/>
        <position ctrllimited="true" ctrlrange="-0.7 0.0" joint="right_outer_knuckle_joint" kp="1" name="gripper_right_outer_knuckle_joint" forcelimited="true" forcerange="-20 20"/>
        <position ctrllimited="true" ctrlrange="0.0 0.7" joint="right_inner_finger_joint" kp="1" name="gripper_right_inner_finger_joint" forcelimited="true" forcerange="-20 20"/>
        <position ctrllimited="true" ctrlrange="-0.7 0.0" joint="right_inner_knuckle_joint" kp="1" name="gripper_right_inner_knuckle_joint" forcelimited="true" forcerange="-20 20"/>
    </actuator>

    <worldbody>
        <geom type="mesh" rgba="0.1 0.1 0.1 1" mesh="robotiq_arg2f_base_link_collision" />
        <site name="grip_site" pos="0 0 0.2" size="0.01" rgba="1 0 0 1" type="sphere" group="1"/>
        <site name="grip_site_cylinder" pos="0 0 0" quat="0 0 0 1" size="0.005 10" rgba="0 1 0 0.3" type="cylinder" group="1"></site>
        <body name="left_outer_knuckle" pos="0 -0.030601 0.054905" quat="-0.410405 -0.911903 0 0">
            <inertial pos="0.000163875 0.0458404 0.0117804" quat="0.881368 0.472423 -0.0024451 -0.000996122" mass="0.0311462" diaginertia="2.96023e-05 2.79814e-05 4.39017e-06" />            
            <joint name="left_outer_knuckle_joint" pos="0 0 0" axis="1 0 0" limited="true" range="-0.7 0.0" />
            <geom type="mesh" rgba="0.792157 0.819608 0.933333 1" mesh="robotiq_arg2f_140_outer_knuckle_collision" name="left_outer_knuckle"/>
            <geom pos="0 0.01822 0.0260018" type="mesh" rgba="0.1 0.1 0.1 1" mesh="robotiq_arg2f_140_outer_finger_collision" name="left_outer_finger"/>
            <body name="left_inner_finger" pos="0 0.0999754 -0.00221853" quat="0.935013 -0.354613 0 0">
                <inertial pos="0.000119314 0.0339244 -0.021841" quat="0.545437 0.430197 -0.442938 0.566776" mass="0.0261503" diaginertia="1.62408e-05 1.59131e-05 2.38936e-06" />                
                <joint name="left_inner_finger_joint" pos="0 0 0" axis="1 0 0" limited="true" range="0.0 0.7" />
                <geom type="mesh" rgba="0.1 0.1 0.1 1" mesh="robotiq_arg2f_140_inner_finger_collision" name="left_inner_finger" />
                <geom size="0.015 0.035 0.00375" pos="0 0.0457554 -0.0272203" type="box" rgba="0.9 0.9 0.9 1" />
            </body>
        </body>
        <body name="left_inner_knuckle" pos="0 -0.0127 0.06142" quat="0.410405 0.911903 0 0">
            <inertial pos="0.000123012 0.0507851 0.00103969" quat="0.497203 0.502496 -0.507943 0.492221" mass="0.0271177" diaginertia="2.83809e-05 2.61936e-05 2.81319e-06" />            
            <joint name="left_inner_knuckle_joint" pos="0 0 0" axis="1 0 0" limited="true" range="-0.7 0.0" />
            <geom type="mesh" rgba="0.1 0.1 0.1 1" mesh="robotiq_arg2f_140_inner_knuckle_collision" name="left_inner_knuckle" />
        </body>
        <body name="right_outer_knuckle" pos="0 0.030601 0.054905" quat="0 0 0.911903 0.410405">
            <inertial pos="0.000163875 0.0458404 0.0117804" quat="0.881368 0.472423 -0.0024451 -0.000996122" mass="0.0311462" diaginertia="2.96023e-05 2.79814e-05 4.39017e-06" />            
            <joint name="right_outer_knuckle_joint" pos="0 0 0" axis="1 0 0" limited="true" range="-0.7 0.0" />
            <geom type="mesh" rgba="0.792157 0.819608 0.933333 1" mesh="robotiq_arg2f_140_outer_knuckle_collision" name="right_outer_knuckle"/>
            <geom pos="0 0.01822 0.0260018" type="mesh" rgba="0.1 0.1 0.1 1" mesh="robotiq_arg2f_140_outer_finger_collision" name="right_outer_finger"/>
            <body name="right_inner_finger" pos="0 0.0999754 -0.00221853" quat="0.935013 -0.354613 0 0">
             <inertial pos="0.000123012 0.0507851 0.00103969" quat="0.497203 0.502496 -0.507943 0.492221" mass="0.0271177" diaginertia="2.83809e-05 2.61936e-05 2.81319e-06" />                
             <joint name="right_inner_finger_joint" pos="0 0 0" axis="1 0 0" limited="true" range="0.0 0.7" />
                <geom type="mesh" rgba="0.1 0.1 0.1 1" mesh="robotiq_arg2f_140_inner_finger_collision" name="right_inner_finger"/>
                <geom size="0.015 0.035 0.00375" pos="0 0.0457554 -0.0272203" type="box" rgba="0.9 0.9 0.9 1" />
            </body>
        </body>
        <body name="right_inner_knuckle" pos="0 0.0127 0.06142" quat="0 0 -0.911903 -0.410405">
            <inertial pos="0.000123012 0.0507851 0.00103969" quat="0.497203 0.502496 -0.507943 0.492221" mass="0.0271177" diaginertia="2.83809e-05 2.61936e-05 2.81319e-06" />            
            <joint name="right_inner_knuckle_joint" pos="0 0 0" axis="1 0 0" limited="true" range="-0.7 0.0" />
            <geom type="mesh" rgba="0.1 0.1 0.1 1" mesh="robotiq_arg2f_140_inner_knuckle_collision" name="right_inner_knuckle" />
        </body>
    </worldbody>

    <contact>
        <exclude body1="left_inner_knuckle" body2="left_outer_knuckle"/>
        <exclude body1="left_inner_knuckle" body2="left_inner_finger"/>
        <exclude body1="right_inner_knuckle" body2="right_outer_knuckle"/>
        <exclude body1="right_inner_knuckle" body2="right_inner_finger"/>
    </contact>

</mujoco>